function NotificationException() {}
function ErrorException() {}
function primitiveMultiply(a, b) {
  const rand = Math.random();
  if (rand < 0.5) {
    return a * b;
  } else if (rand > 0.85) {
    throw new ErrorException();
  } else {
    throw new NotificationException();
  }
}

function reliableMultiply(a, b) {
  while (true) {
    try {
      return primitiveMultiply(a, b);
    } catch (error) {
      if (error instanceof ErrorException) {
        throw error; =
      } else if (error instanceof NotificationException) {
        document.write("NotificationException occurred. Retrying...");
      } else {
        throw error;
      }
    }
  }
}

try {
  document.write(reliableMultiply(8, 8));
} catch (error) {
  document.write("An ErrorException occurred:", error);
}
